<?xml version="1.0"?>
<robot name="generic_humanoid">
  <!--
    This is a lightweight, repo-local humanoid URDF to unblock pipeline work.
    It is NOT tuned for sim-to-real. Swap with a real asset (e.g., Unitree G1) when licensed/available.
  -->

  <link name="pelvis">
    <inertial>
      <origin xyz="0 0 0" rpy="0 0 0"/>
      <mass value="10.0"/>
      <inertia ixx="0.20" ixy="0" ixz="0" iyy="0.20" iyz="0" izz="0.20"/>
    </inertial>
    <visual>
      <origin xyz="0 0 0" rpy="0 0 0"/>
      <geometry>
        <box size="0.30 0.20 0.10"/>
      </geometry>
    </visual>
    <collision>
      <origin xyz="0 0 0" rpy="0 0 0"/>
      <geometry>
        <box size="0.30 0.20 0.10"/>
      </geometry>
    </collision>
  </link>

  <link name="torso_yaw_link">
    <inertial>
      <origin xyz="0 0 0" rpy="0 0 0"/>
      <mass value="8.0"/>
      <inertia ixx="0.15" ixy="0" ixz="0" iyy="0.15" iyz="0" izz="0.10"/>
    </inertial>
    <visual>
      <origin xyz="0 0 0.15" rpy="0 0 0"/>
      <geometry>
        <box size="0.30 0.20 0.30"/>
      </geometry>
    </visual>
    <collision>
      <origin xyz="0 0 0.15" rpy="0 0 0"/>
      <geometry>
        <box size="0.30 0.20 0.30"/>
      </geometry>
    </collision>
  </link>

  <joint name="torso_yaw" type="revolute">
    <parent link="pelvis"/>
    <child link="torso_yaw_link"/>
    <origin xyz="0 0 0.08" rpy="0 0 0"/>
    <axis xyz="0 0 1"/>
    <limit lower="-1.57" upper="1.57" effort="150" velocity="5.0"/>
  </joint>

  <link name="torso">
    <inertial>
      <origin xyz="0 0 0" rpy="0 0 0"/>
      <mass value="8.0"/>
      <inertia ixx="0.15" ixy="0" ixz="0" iyy="0.15" iyz="0" izz="0.10"/>
    </inertial>
    <visual>
      <origin xyz="0 0 0.15" rpy="0 0 0"/>
      <geometry>
        <box size="0.32 0.22 0.35"/>
      </geometry>
    </visual>
    <collision>
      <origin xyz="0 0 0.15" rpy="0 0 0"/>
      <geometry>
        <box size="0.32 0.22 0.35"/>
      </geometry>
    </collision>
  </link>

  <joint name="torso_pitch" type="revolute">
    <parent link="torso_yaw_link"/>
    <child link="torso"/>
    <origin xyz="0 0 0.25" rpy="0 0 0"/>
    <axis xyz="0 1 0"/>
    <limit lower="-0.78" upper="0.78" effort="150" velocity="5.0"/>
  </joint>

  <link name="head">
    <inertial>
      <origin xyz="0 0 0" rpy="0 0 0"/>
      <mass value="3.0"/>
      <inertia ixx="0.02" ixy="0" ixz="0" iyy="0.02" iyz="0" izz="0.02"/>
    </inertial>
    <visual>
      <origin xyz="0 0 0.05" rpy="0 0 0"/>
      <geometry>
        <sphere radius="0.10"/>
      </geometry>
    </visual>
    <collision>
      <origin xyz="0 0 0.05" rpy="0 0 0"/>
      <geometry>
        <sphere radius="0.10"/>
      </geometry>
    </collision>
  </link>

  <joint name="neck_fixed" type="fixed">
    <parent link="torso"/>
    <child link="head"/>
    <origin xyz="0 0 0.35" rpy="0 0 0"/>
  </joint>

  <!-- Left arm -->
  <link name="left_shoulder_pitch_link">
    <inertial>
      <origin xyz="0 0 0" rpy="0 0 0"/>
      <mass value="1.0"/>
      <inertia ixx="0.01" ixy="0" ixz="0" iyy="0.01" iyz="0" izz="0.01"/>
    </inertial>
  </link>

  <joint name="left_shoulder_pitch" type="revolute">
    <parent link="torso"/>
    <child link="left_shoulder_pitch_link"/>
    <origin xyz="0.00 0.16 0.28" rpy="0 0 0"/>
    <axis xyz="0 1 0"/>
    <limit lower="-1.57" upper="1.57" effort="80" velocity="6.0"/>
  </joint>

  <link name="left_shoulder_roll_link">
    <inertial>
      <origin xyz="0 0 0" rpy="0 0 0"/>
      <mass value="1.0"/>
      <inertia ixx="0.01" ixy="0" ixz="0" iyy="0.01" iyz="0" izz="0.01"/>
    </inertial>
  </link>

  <joint name="left_shoulder_roll" type="revolute">
    <parent link="left_shoulder_pitch_link"/>
    <child link="left_shoulder_roll_link"/>
    <origin xyz="0 0 0" rpy="0 0 0"/>
    <axis xyz="1 0 0"/>
    <limit lower="-1.57" upper="1.57" effort="80" velocity="6.0"/>
  </joint>

  <link name="left_upper_arm">
    <inertial>
      <origin xyz="0 0 0" rpy="0 0 0"/>
      <mass value="2.0"/>
      <inertia ixx="0.02" ixy="0" ixz="0" iyy="0.02" iyz="0" izz="0.01"/>
    </inertial>
    <visual>
      <origin xyz="0 0 0.15" rpy="0 0 0"/>
      <geometry>
        <cylinder radius="0.04" length="0.30"/>
      </geometry>
    </visual>
    <collision>
      <origin xyz="0 0 0.15" rpy="0 0 0"/>
      <geometry>
        <cylinder radius="0.04" length="0.30"/>
      </geometry>
    </collision>
  </link>

  <joint name="left_shoulder_yaw" type="revolute">
    <parent link="left_shoulder_roll_link"/>
    <child link="left_upper_arm"/>
    <origin xyz="0 0 0" rpy="0 0 0"/>
    <axis xyz="0 0 1"/>
    <limit lower="-2.35" upper="2.35" effort="80" velocity="6.0"/>
  </joint>

  <link name="left_forearm">
    <inertial>
      <origin xyz="0 0 0" rpy="0 0 0"/>
      <mass value="1.5"/>
      <inertia ixx="0.02" ixy="0" ixz="0" iyy="0.02" iyz="0" izz="0.01"/>
    </inertial>
    <visual>
      <origin xyz="0 0 0.13" rpy="0 0 0"/>
      <geometry>
        <cylinder radius="0.035" length="0.26"/>
      </geometry>
    </visual>
    <collision>
      <origin xyz="0 0 0.13" rpy="0 0 0"/>
      <geometry>
        <cylinder radius="0.035" length="0.26"/>
      </geometry>
    </collision>
  </link>

  <joint name="left_elbow" type="revolute">
    <parent link="left_upper_arm"/>
    <child link="left_forearm"/>
    <origin xyz="0 0 0.30" rpy="0 0 0"/>
    <axis xyz="0 1 0"/>
    <limit lower="-2.35" upper="0.0" effort="60" velocity="6.0"/>
  </joint>

  <link name="left_hand">
    <inertial>
      <origin xyz="0 0 0" rpy="0 0 0"/>
      <mass value="0.5"/>
      <inertia ixx="0.005" ixy="0" ixz="0" iyy="0.005" iyz="0" izz="0.005"/>
    </inertial>
    <visual>
      <origin xyz="0 0 0.05" rpy="0 0 0"/>
      <geometry>
        <box size="0.10 0.08 0.10"/>
      </geometry>
    </visual>
    <collision>
      <origin xyz="0 0 0.05" rpy="0 0 0"/>
      <geometry>
        <box size="0.10 0.08 0.10"/>
      </geometry>
    </collision>
  </link>

  <joint name="left_wrist" type="revolute">
    <parent link="left_forearm"/>
    <child link="left_hand"/>
    <origin xyz="0 0 0.26" rpy="0 0 0"/>
    <axis xyz="1 0 0"/>
    <limit lower="-1.57" upper="1.57" effort="30" velocity="8.0"/>
  </joint>

  <!-- Right arm -->
  <link name="right_shoulder_pitch_link">
    <inertial>
      <origin xyz="0 0 0" rpy="0 0 0"/>
      <mass value="1.0"/>
      <inertia ixx="0.01" ixy="0" ixz="0" iyy="0.01" iyz="0" izz="0.01"/>
    </inertial>
  </link>

  <joint name="right_shoulder_pitch" type="revolute">
    <parent link="torso"/>
    <child link="right_shoulder_pitch_link"/>
    <origin xyz="0.00 -0.16 0.28" rpy="0 0 0"/>
    <axis xyz="0 1 0"/>
    <limit lower="-1.57" upper="1.57" effort="80" velocity="6.0"/>
  </joint>

  <link name="right_shoulder_roll_link">
    <inertial>
      <origin xyz="0 0 0" rpy="0 0 0"/>
      <mass value="1.0"/>
      <inertia ixx="0.01" ixy="0" ixz="0" iyy="0.01" iyz="0" izz="0.01"/>
    </inertial>
  </link>

  <joint name="right_shoulder_roll" type="revolute">
    <parent link="right_shoulder_pitch_link"/>
    <child link="right_shoulder_roll_link"/>
    <origin xyz="0 0 0" rpy="0 0 0"/>
    <axis xyz="1 0 0"/>
    <limit lower="-1.57" upper="1.57" effort="80" velocity="6.0"/>
  </joint>

  <link name="right_upper_arm">
    <inertial>
      <origin xyz="0 0 0" rpy="0 0 0"/>
      <mass value="2.0"/>
      <inertia ixx="0.02" ixy="0" ixz="0" iyy="0.02" iyz="0" izz="0.01"/>
    </inertial>
    <visual>
      <origin xyz="0 0 0.15" rpy="0 0 0"/>
      <geometry>
        <cylinder radius="0.04" length="0.30"/>
      </geometry>
    </visual>
    <collision>
      <origin xyz="0 0 0.15" rpy="0 0 0"/>
      <geometry>
        <cylinder radius="0.04" length="0.30"/>
      </geometry>
    </collision>
  </link>

  <joint name="right_shoulder_yaw" type="revolute">
    <parent link="right_shoulder_roll_link"/>
    <child link="right_upper_arm"/>
    <origin xyz="0 0 0" rpy="0 0 0"/>
    <axis xyz="0 0 1"/>
    <limit lower="-2.35" upper="2.35" effort="80" velocity="6.0"/>
  </joint>

  <link name="right_forearm">
    <inertial>
      <origin xyz="0 0 0" rpy="0 0 0"/>
      <mass value="1.5"/>
      <inertia ixx="0.02" ixy="0" ixz="0" iyy="0.02" iyz="0" izz="0.01"/>
    </inertial>
    <visual>
      <origin xyz="0 0 0.13" rpy="0 0 0"/>
      <geometry>
        <cylinder radius="0.035" length="0.26"/>
      </geometry>
    </visual>
    <collision>
      <origin xyz="0 0 0.13" rpy="0 0 0"/>
      <geometry>
        <cylinder radius="0.035" length="0.26"/>
      </geometry>
    </collision>
  </link>

  <joint name="right_elbow" type="revolute">
    <parent link="right_upper_arm"/>
    <child link="right_forearm"/>
    <origin xyz="0 0 0.30" rpy="0 0 0"/>
    <axis xyz="0 1 0"/>
    <limit lower="-2.35" upper="0.0" effort="60" velocity="6.0"/>
  </joint>

  <link name="right_hand">
    <inertial>
      <origin xyz="0 0 0" rpy="0 0 0"/>
      <mass value="0.5"/>
      <inertia ixx="0.005" ixy="0" ixz="0" iyy="0.005" iyz="0" izz="0.005"/>
    </inertial>
    <visual>
      <origin xyz="0 0 0.05" rpy="0 0 0"/>
      <geometry>
        <box size="0.10 0.08 0.10"/>
      </geometry>
    </visual>
    <collision>
      <origin xyz="0 0 0.05" rpy="0 0 0"/>
      <geometry>
        <box size="0.10 0.08 0.10"/>
      </geometry>
    </collision>
  </link>

  <joint name="right_wrist" type="revolute">
    <parent link="right_forearm"/>
    <child link="right_hand"/>
    <origin xyz="0 0 0.26" rpy="0 0 0"/>
    <axis xyz="1 0 0"/>
    <limit lower="-1.57" upper="1.57" effort="30" velocity="8.0"/>
  </joint>

  <!-- Left leg -->
  <link name="left_hip_yaw_link">
    <inertial>
      <origin xyz="0 0 0" rpy="0 0 0"/>
      <mass value="2.0"/>
      <inertia ixx="0.02" ixy="0" ixz="0" iyy="0.02" iyz="0" izz="0.02"/>
    </inertial>
  </link>

  <joint name="left_hip_yaw" type="revolute">
    <parent link="pelvis"/>
    <child link="left_hip_yaw_link"/>
    <origin xyz="0.00 0.10 -0.02" rpy="0 0 0"/>
    <axis xyz="0 0 1"/>
    <limit lower="-1.57" upper="1.57" effort="150" velocity="6.0"/>
  </joint>

  <link name="left_hip_roll_link">
    <inertial>
      <origin xyz="0 0 0" rpy="0 0 0"/>
      <mass value="2.0"/>
      <inertia ixx="0.02" ixy="0" ixz="0" iyy="0.02" iyz="0" izz="0.02"/>
    </inertial>
  </link>

  <joint name="left_hip_roll" type="revolute">
    <parent link="left_hip_yaw_link"/>
    <child link="left_hip_roll_link"/>
    <origin xyz="0 0 0" rpy="0 0 0"/>
    <axis xyz="1 0 0"/>
    <limit lower="-0.78" upper="0.78" effort="150" velocity="6.0"/>
  </joint>

  <link name="left_thigh">
    <inertial>
      <origin xyz="0 0 0" rpy="0 0 0"/>
      <mass value="5.0"/>
      <inertia ixx="0.10" ixy="0" ixz="0" iyy="0.10" iyz="0" izz="0.05"/>
    </inertial>
    <visual>
      <origin xyz="0 0 -0.18" rpy="0 0 0"/>
      <geometry>
        <cylinder radius="0.06" length="0.36"/>
      </geometry>
    </visual>
    <collision>
      <origin xyz="0 0 -0.18" rpy="0 0 0"/>
      <geometry>
        <cylinder radius="0.06" length="0.36"/>
      </geometry>
    </collision>
  </link>

  <joint name="left_hip_pitch" type="revolute">
    <parent link="left_hip_roll_link"/>
    <child link="left_thigh"/>
    <origin xyz="0 0 0" rpy="0 0 0"/>
    <axis xyz="0 1 0"/>
    <limit lower="-1.57" upper="1.57" effort="150" velocity="6.0"/>
  </joint>

  <link name="left_shin">
    <inertial>
      <origin xyz="0 0 0" rpy="0 0 0"/>
      <mass value="4.0"/>
      <inertia ixx="0.08" ixy="0" ixz="0" iyy="0.08" iyz="0" izz="0.04"/>
    </inertial>
    <visual>
      <origin xyz="0 0 -0.18" rpy="0 0 0"/>
      <geometry>
        <cylinder radius="0.055" length="0.36"/>
      </geometry>
    </visual>
    <collision>
      <origin xyz="0 0 -0.18" rpy="0 0 0"/>
      <geometry>
        <cylinder radius="0.055" length="0.36"/>
      </geometry>
    </collision>
  </link>

  <joint name="left_knee" type="revolute">
    <parent link="left_thigh"/>
    <child link="left_shin"/>
    <origin xyz="0 0 -0.36" rpy="0 0 0"/>
    <axis xyz="0 1 0"/>
    <limit lower="0.0" upper="2.35" effort="150" velocity="6.0"/>
  </joint>

  <link name="left_ankle_pitch_link">
    <inertial>
      <origin xyz="0 0 0" rpy="0 0 0"/>
      <mass value="1.0"/>
      <inertia ixx="0.01" ixy="0" ixz="0" iyy="0.01" iyz="0" izz="0.01"/>
    </inertial>
  </link>

  <joint name="left_ankle_pitch" type="revolute">
    <parent link="left_shin"/>
    <child link="left_ankle_pitch_link"/>
    <origin xyz="0 0 -0.36" rpy="0 0 0"/>
    <axis xyz="0 1 0"/>
    <limit lower="-0.78" upper="0.78" effort="80" velocity="8.0"/>
  </joint>

  <link name="left_foot">
    <inertial>
      <origin xyz="0 0 0" rpy="0 0 0"/>
      <mass value="1.0"/>
      <inertia ixx="0.01" ixy="0" ixz="0" iyy="0.01" iyz="0" izz="0.01"/>
    </inertial>
    <visual>
      <origin xyz="0.05 0 -0.03" rpy="0 0 0"/>
      <geometry>
        <box size="0.22 0.10 0.06"/>
      </geometry>
    </visual>
    <collision>
      <origin xyz="0.05 0 -0.03" rpy="0 0 0"/>
      <geometry>
        <box size="0.22 0.10 0.06"/>
      </geometry>
    </collision>
  </link>

  <joint name="left_ankle_roll" type="revolute">
    <parent link="left_ankle_pitch_link"/>
    <child link="left_foot"/>
    <origin xyz="0 0 0" rpy="0 0 0"/>
    <axis xyz="1 0 0"/>
    <limit lower="-0.52" upper="0.52" effort="80" velocity="8.0"/>
  </joint>

  <!-- Right leg -->
  <link name="right_hip_yaw_link">
    <inertial>
      <origin xyz="0 0 0" rpy="0 0 0"/>
      <mass value="2.0"/>
      <inertia ixx="0.02" ixy="0" ixz="0" iyy="0.02" iyz="0" izz="0.02"/>
    </inertial>
  </link>

  <joint name="right_hip_yaw" type="revolute">
    <parent link="pelvis"/>
    <child link="right_hip_yaw_link"/>
    <origin xyz="0.00 -0.10 -0.02" rpy="0 0 0"/>
    <axis xyz="0 0 1"/>
    <limit lower="-1.57" upper="1.57" effort="150" velocity="6.0"/>
  </joint>

  <link name="right_hip_roll_link">
    <inertial>
      <origin xyz="0 0 0" rpy="0 0 0"/>
      <mass value="2.0"/>
      <inertia ixx="0.02" ixy="0" ixz="0" iyy="0.02" iyz="0" izz="0.02"/>
    </inertial>
  </link>

  <joint name="right_hip_roll" type="revolute">
    <parent link="right_hip_yaw_link"/>
    <child link="right_hip_roll_link"/>
    <origin xyz="0 0 0" rpy="0 0 0"/>
    <axis xyz="1 0 0"/>
    <limit lower="-0.78" upper="0.78" effort="150" velocity="6.0"/>
  </joint>

  <link name="right_thigh">
    <inertial>
      <origin xyz="0 0 0" rpy="0 0 0"/>
      <mass value="5.0"/>
      <inertia ixx="0.10" ixy="0" ixz="0" iyy="0.10" iyz="0" izz="0.05"/>
    </inertial>
    <visual>
      <origin xyz="0 0 -0.18" rpy="0 0 0"/>
      <geometry>
        <cylinder radius="0.06" length="0.36"/>
      </geometry>
    </visual>
    <collision>
      <origin xyz="0 0 -0.18" rpy="0 0 0"/>
      <geometry>
        <cylinder radius="0.06" length="0.36"/>
      </geometry>
    </collision>
  </link>

  <joint name="right_hip_pitch" type="revolute">
    <parent link="right_hip_roll_link"/>
    <child link="right_thigh"/>
    <origin xyz="0 0 0" rpy="0 0 0"/>
    <axis xyz="0 1 0"/>
    <limit lower="-1.57" upper="1.57" effort="150" velocity="6.0"/>
  </joint>

  <link name="right_shin">
    <inertial>
      <origin xyz="0 0 0" rpy="0 0 0"/>
      <mass value="4.0"/>
      <inertia ixx="0.08" ixy="0" ixz="0" iyy="0.08" iyz="0" izz="0.04"/>
    </inertial>
    <visual>
      <origin xyz="0 0 -0.18" rpy="0 0 0"/>
      <geometry>
        <cylinder radius="0.055" length="0.36"/>
      </geometry>
    </visual>
    <collision>
      <origin xyz="0 0 -0.18" rpy="0 0 0"/>
      <geometry>
        <cylinder radius="0.055" length="0.36"/>
      </geometry>
    </collision>
  </link>

  <joint name="right_knee" type="revolute">
    <parent link="right_thigh"/>
    <child link="right_shin"/>
    <origin xyz="0 0 -0.36" rpy="0 0 0"/>
    <axis xyz="0 1 0"/>
    <limit lower="0.0" upper="2.35" effort="150" velocity="6.0"/>
  </joint>

  <link name="right_ankle_pitch_link">
    <inertial>
      <origin xyz="0 0 0" rpy="0 0 0"/>
      <mass value="1.0"/>
      <inertia ixx="0.01" ixy="0" ixz="0" iyy="0.01" iyz="0" izz="0.01"/>
    </inertial>
  </link>

  <joint name="right_ankle_pitch" type="revolute">
    <parent link="right_shin"/>
    <child link="right_ankle_pitch_link"/>
    <origin xyz="0 0 -0.36" rpy="0 0 0"/>
    <axis xyz="0 1 0"/>
    <limit lower="-0.78" upper="0.78" effort="80" velocity="8.0"/>
  </joint>

  <link name="right_foot">
    <inertial>
      <origin xyz="0 0 0" rpy="0 0 0"/>
      <mass value="1.0"/>
      <inertia ixx="0.01" ixy="0" ixz="0" iyy="0.01" iyz="0" izz="0.01"/>
    </inertial>
    <visual>
      <origin xyz="0.05 0 -0.03" rpy="0 0 0"/>
      <geometry>
        <box size="0.22 0.10 0.06"/>
      </geometry>
    </visual>
    <collision>
      <origin xyz="0.05 0 -0.03" rpy="0 0 0"/>
      <geometry>
        <box size="0.22 0.10 0.06"/>
      </geometry>
    </collision>
  </link>

  <joint name="right_ankle_roll" type="revolute">
    <parent link="right_ankle_pitch_link"/>
    <child link="right_foot"/>
    <origin xyz="0 0 0" rpy="0 0 0"/>
    <axis xyz="1 0 0"/>
    <limit lower="-0.52" upper="0.52" effort="80" velocity="8.0"/>
  </joint>
</robot>
